<?xml version="1.0"?>

<robot name="base" xmlns:xacro="http://ros.org/wiki/xacro">
<link name="base_footprint">
<inertial>
         <mass value="0.000001" />
         <origin xyz="0 0 0.5" />
         <inertia ixx="0.0001" ixy="0.0" ixz="0.0"
            iyy="0.0001" iyz="0.0"
            izz="0.0001" />
         </inertial>
  <visual>
        <origin xyz="0 0 0.5" rpy="0 0 0" />
        <geometry>
          <cylinder radius= "0.1" length="1"/>
        </geometry> 
        <material name="Cyan">
       <color rgba="0 1.0 1.0 1.0"/>
     </material>       
      </visual>  
  <collision>
        <origin xyz="0 0 0.5" rpy="0 0 0" />
        <geometry>
          <cylinder radius= "0.1" length="1"/>
        </geometry>
      </collision> 
       
</link>

<link name="wheel">
<inertial>
         <mass value="0.000001" />
         <origin xyz="0 0 0.5" />
         <inertia ixx="0.0001" ixy="0.0" ixz="0.0"
            iyy="0.0001" iyz="0.0"
            izz="0.0001" />
         </inertial>
  <visual>
        <origin xyz="-0.105 -0.1 0.05" rpy="0 1.57 0" />
        <geometry>
                 <mesh filename="package://rbt_description/meshes/p.STL" scale="0.01 0.01 0.01"/>
          
        </geometry> 
              
      </visual>  
  <collision>
        <origin xyz="0 0 0.5" rpy="0 0 0" />
        <geometry>
          <cylinder radius= "0.1" length="1"/>
        </geometry>
      </collision> 
       
</link>
<joint name="joint" type="revolute">
         <origin xyz="0 0 1.00" rpy="0 0 0" />
          <parent link="base_footprint" />
          <child link="wheel" />
          <axis xyz="1 0 0" />
          <limit effort="1000.0" lower="-0.5" upper="0.548" velocity="0.5"/>
      </joint>
</robot>