<?xml version="1.0"?>
<robot name="rbt" xmlns:xacro="http://www.ros.org/wiki/xacro">
 <xacro:include filename="$(find rbt_gazebo)/robots/rbt.gazebo.xacro" />
  
  <link
    name="base_link">
    <inertial>
      <origin
        xyz="-0.0015246 0.1504 0.017729"
        rpy="0 0 0" />
      <mass
        value="439.78" />
      <inertia
        ixx="0"
        ixy="0"
        ixz="0"
        iyy="0"
        iyz="0"
        izz="0" />
    </inertial>
    <visual>
      <origin
        xyz="0 0 0"
        rpy="0 0 0" />
      <geometry>
        <mesh
          filename="package://rbt_description/meshes/base_link.STL" />
      </geometry>
      <material
        name="">
        <color
          rgba="0.52941 0.54902 0.54902 1" />
      </material>
    </visual>
    <collision>
      <origin
        xyz="0 0 0"
        rpy="0 0 0" />
      <geometry>
        <mesh
          filename="package://rbt_description/meshes/base_link.STL" />
      </geometry>
    </collision>
  </link>
  <link
    name="r_wheel_link">
    <inertial>
      <origin
        xyz="6.9389E-18 9.7145E-17 -0.015"
        rpy="0 0 0" />
      <mass
        value="0.14401" />
      <inertia
        ixx="0"
        ixy="0"
        ixz="0"
        iyy="0"
        iyz="0"
        izz="0" />
    </inertial>
    <visual>
      <origin
        xyz="0 0 0"
        rpy="0 0 0" />
      <geometry>
        <mesh
          filename="package://rbt_description/meshes/r_wheel_link.STL" />
      </geometry>
      <material
        name="">
        <color
          rgba="0.0078431 0 0.027451 1" />
      </material>
    </visual>
    <collision>
      <origin
        xyz="0 0 0"
        rpy="0 0 0" />
      <geometry>
        <mesh
          filename="package://rbt_description/meshes/r_wheel_link.STL" />
      </geometry>
    </collision>
  </link>
  <joint
    name="r_wheel_joint"
    type="continuous">
    <origin
      xyz="0.175 -0.1 0.05"
      rpy="1.5708 1.4293 -1.5708" />
    <parent
      link="base_link" />
    <child
      link="r_wheel_link" />
    <axis
      xyz="0 0 -1" />
  </joint>
  <link
    name="l_wheel_link">
    <inertial>
      <origin
        xyz="6.9389E-18 9.7145E-17 0.015"
        rpy="0 0 0" />
      <mass
        value="0.14401" />
      <inertia
        ixx="0"
        ixy="0"
        ixz="0"
        iyy="0"
        iyz="0"
        izz="0" />
    </inertial>
    <visual>
      <origin
        xyz="0 0 0"
        rpy="0 0 0" />
      <geometry>
        <mesh
          filename="package://rbt_description/meshes/l_wheel_link.STL" />
      </geometry>
      <material
        name="">
        <color
          rgba="0.0078431 0 0.027451 1" />
      </material>
    </visual>
    <collision>
      <origin
        xyz="0 0 0"
        rpy="0 0 0" />
      <geometry>
        <mesh
          filename="package://rbt_description/meshes/l_wheel_link.STL" />
      </geometry>
    </collision>
  </link>
  <joint
    name="l_wheel_joint"
    type="continuous">
    <origin
      xyz="-0.175 -0.1 0.05"
      rpy="1.5708 1.4293 -1.5708" />
    <parent
      link="base_link" />
    <child
      link="l_wheel_link" />
    <axis
      xyz="0 0 -1" />
  </joint>
</robot>