<?xml version="1.0"?>
<robot name="rbt" xmlns:xacro="http://www.ros.org/wiki/xacro">
 <xacro:include filename="$(find rbt_gazebo)/robots/rbt.gazebo.xacro" />
  
 <link
    name="base_link">
    <inertial>
      <origin
        xyz="0.0015246 0.1254 -0.017729"
        rpy="0 0 0" />
      <mass
        value="70" />
      <inertia
        ixx="1.225"
        ixy="0.0099"
        ixz="0.0062"
        iyy="1.2853"
        iyz="-0.0034"
        izz="0.987" />
    </inertial>
    <visual>
      <origin
        xyz="0 0 0"
        rpy="0 0 0" />
      <geometry>
        <mesh
          filename="package://rbt_description/meshes/base_link.STL" />
      </geometry>
      <material
        name="">
        <color
          rgba="0.52941 0.54902 0.54902 1" />
      </material>
    </visual>
    <collision>
      <origin
        xyz="0 0 0"
        rpy="0 0 0" />
      <geometry>
        <mesh
          filename="package://rbt_description/meshes/base_link.STL" />
      </geometry>
    </collision>
  </link>
  <link
    name="l_wheel_link">
    <inertial>
      <origin
        xyz="6.8001E-16 3.4694E-18 0.19"
        rpy="0 0 0" />
      <mass
        value="4.3542" />
      <inertia
        ixx="0.0045"
        ixy="0"
        ixz="0"
        iyy="0.005"
        iyz="0"
        izz="0.0045" />
    </inertial>
    <visual>
      <origin
        xyz="0 0 0"
        rpy="0 0 0" />
      <geometry>
        <mesh
          filename="package://rbt_description/meshes/l_wheel_link.STL" />
      </geometry>
      <material
        name="">
        <color
          rgba="0.0078431 0 0.027451 1" />
      </material>
    </visual>
    <collision>
      <origin
        xyz="0 0 0"
        rpy="0 0 0" />
      <geometry>
        <mesh
          filename="package://rbt_description/meshes/l_wheel_link.STL" />
      </geometry>
    </collision>
  </link>
  <joint
    name="l_wheel_joint"
    type="continuous">
    <origin
      xyz="0 0.1 0.025"
      rpy="1.5708 6.123E-17 1.5708" />
    <parent
      link="base_link" />
    <child
      link="l_wheel_link" />
    <axis
      xyz="0 0 1" />
    <limit
      effort="8.85"
      velocity="17.4" />
  </joint>
  <link
    name="r_wheel_link">
    <inertial>
      <origin
        xyz="-1.2351E-15 0 -0.025524"
        rpy="0 0 0" />
      <mass
        value="0.14401" />
      <inertia
        ixx="0.0045"
        ixy="0"
        ixz="0"
        iyy="0.005"
        iyz="0"
        izz="0.0045" />
    </inertial>
    <visual>
      <origin
        xyz="0 0 0"
        rpy="0 0 0" />
      <geometry>
        <mesh
          filename="package://rbt_description/meshes/r_wheel_link.STL" />
      </geometry>
      <material
        name="">
        <color
          rgba="0.0078431 0 0.027451 1" />
      </material>
    </visual>
    <collision>
      <origin
        xyz="0 0 0"
        rpy="0 0 0" />
      <geometry>
        <mesh
          filename="package://rbt_description/meshes/r_wheel_link.STL" />
      </geometry>
    </collision>
  </link>
  <joint
    name="r_wheel_joint"
    type="continuous">
    <origin
      xyz="-0.16448 0.1 0.025"
      rpy="1.5708 6.123E-17 1.5708" />
    <parent
      link="base_link" />
    <child
      link="r_wheel_link" />
    <axis
      xyz="0 0 1" />
    <limit
      effort="8.85"
      velocity="17.4" />
  </joint>
</robot>