<robot
  name="rbt">
  <link
    name="base_link">
    <inertial>
      <origin
        xyz="0.00249189384812189 -1.57266312588598E-10 0.132977386791425"
        rpy="0 0 0" />
      <mass
        value="34.8310964963823" />
      <inertia
        ixx="0.169235422161565"
        ixy="-1.36500224779735E-11"
        ixz="0.00632442399133717"
        iyy="0.156418904598816"
        iyz="-3.22056686985752E-10"
        izz="0.0347596628732701" />
    </inertial>
    <visual>
      <origin
        xyz="0 0 0"
        rpy="0 0 0" />
      <geometry>
        <mesh
          filename="package://rbt_description/meshes/base_link.dae" />
      </geometry>
      <material
        name="">
        <color
          rgba="0.752941176470588 0.752941176470588 0.752941176470588 1" />
      </material>
    </visual>
    <collision>
      <origin
        xyz="0 0 0"
        rpy="0 0 0" />
      <geometry>
        <mesh
          filename="package://rbt_description/meshes/base_link.STL" />
      </geometry>
    </collision>
  </link>
  <link
    name="l_wheel_link">
    <inertial>
      <origin
        xyz="0 0 0"
        rpy="0 0 0" />
      <mass
        value="3.8838" />
     <inertia ixx="0.0045" ixy="0" ixz="0" iyy="0.005" iyz="0" izz="0.0045" />
    </inertial>
    <visual>
      <origin
        xyz="0 0 0"
        rpy="0 0 0" />
      <geometry>
        <mesh
          filename="package://rbt_description/meshes/l_wheel_link.dae" />
      </geometry>
      <material
        name="">
        <color
          rgba="0.15294 1 0.97255 1" />
      </material>
    </visual>
    <collision>
      <origin
        xyz="0 0 0"
        rpy="0 0 0" />
      <geometry>
        <mesh
          filename="package://rbt_description/meshes/l_wheel_link.STL" />
      </geometry>
    </collision>
  </link>
  <joint
    name="l_wheel_joint"
    type="continuous">
    <origin
      xyz="-0.12 0.175 0.07"
      rpy="1.5777E-30 -2.3314E-29 -3.2868E-15" />
    <parent
      link="base_link" />
    <child
      link="l_wheel_link" />
    <axis
      xyz="0 1 0" />
  </joint>
  <link
    name="r_wheel_link">
    <inertial>
      <origin
        xyz="0 -2.7756E-17 0"
        rpy="0 0 0" />
      <mass
        value="3.8838" />
      <inertia ixx="0.0045" ixy="0" ixz="0" iyy="0.005" iyz="0" izz="0.0045" />
    </inertial>
    <visual>
      <origin
        xyz="0 0 0"
        rpy="0 0 0" />
      <geometry>
        <mesh
          filename="package://rbt_description/meshes/r_wheel_link.dae" />
      </geometry>
      <material
        name="">
        <color
          rgba="0.15294 1 0.97255 1" />
      </material>
    </visual>
    <collision>
      <origin
        xyz="0 0 0"
        rpy="0 0 0" />
      <geometry>
        <mesh
          filename="package://rbt_description/meshes/r_wheel_link.STL" />
      </geometry>
    </collision>
  </link>
  <joint
    name="r_wheel_joint"
    type="continuous">
    <origin
      xyz="-0.12 -0.175 0.07"
      rpy="1.5777E-30 -2.3314E-29 -3.2868E-15" />
    <parent
      link="base_link" />
    <child
      link="r_wheel_link" />
    <axis
      xyz="0 1 0" />
  </joint>
  <link
    name="laser_link">
    <inertial>
      <origin
        xyz="2.7756E-17 -2.8995E-17 -0.0042085"
        rpy="0 0 0" />
      <mass value="0.11769" />
      <inertia ixx="1.01866461240801E-06" ixy="-5.88447626567756E-08" ixz="7.83857244757914E-08" iyy="5.10039589974707E-07" iyz="-7.12664289617235E-09" izz="1.28270671527309E-06" />
    </inertial>
    <visual>
      <origin
        xyz="0 0 0"
        rpy="0 0 0" />
      <geometry>
        <mesh
          filename="package://rbt_description/meshes/laser_link.dae" />
      </geometry>
      <material
        name="">
        <color
          rgba="0.79216 0.81961 0.93333 1" />
      </material>
    </visual>
    <collision>
      <origin
        xyz="0 0 0"
        rpy="0 0 0" />
      <geometry>
        <mesh
          filename="package://rbt_description/meshes/laser_link.STL" />
      </geometry>
    </collision>
  </link>
  <joint
    name="laser_joint"
    type="fixed">
    <origin
      xyz="0.165 0 0.257"
      rpy="1.5777E-30 -2.3314E-29 -3.2868E-15" />
    <parent
      link="base_link" />
    <child
      link="laser_link" />
    <axis
      xyz="0 0 0" />
  </joint>
  <link
    name="torso_link">
    <inertial>
      <origin
        xyz="0.00513888551273761 -2.86582418452393E-08 0.355264410428356"
        rpy="0 0 0" />
      <mass value="13.2775" />
      <inertia ixx="0.3861" ixy="0.0015" ixz="-0.0102" iyy="0.3388" iyz="0.0117" izz="0.1018" />
    </inertial>
    <visual>
      <origin
        xyz="0 0 0"
        rpy="0 0 0" />
      <geometry>
        <mesh
          filename="package://rbt_description/meshes/torso_link.STL" />
      </geometry>
      <material
        name="">
        <color
          rgba="1 1 1 1" />
      </material>
    </visual>
    <collision>
      <origin
        xyz="0 0 0"
        rpy="0 0 0" />
      <geometry>
        <mesh
          filename="package://rbt_description/meshes/torso_link.STL" />
      </geometry>
    </collision>
  </link>
  <joint
    name="torso_joint"
    type="fixed">
    <origin
      xyz="-0.19 0 0.225"
      rpy="-3.47545734981105E-43 1.01364733915118E-30 0" />
    <parent
      link="base_link" />
    <child
      link="torso_link" />
    <axis
      xyz="0 0 0" />
  </joint>
  <link
    name="shoulder_pan_link">
    <inertial>
      <origin
        xyz="0.0596224021144385 0.000252610505440617 0.0574346028564235"
        rpy="0 0 0" />
     <mass value="2.5587" />
      <inertia ixx="0.0043" ixy="-0.0001" ixz="0.001" iyy="0.0087" iyz="-0.0001" izz="0.0087" />
    </inertial>
    <visual>
      <origin
        xyz="0 0 0"
        rpy="0 0 0" />
      <geometry>
        <mesh
          filename="package://rbt_description/meshes/shoulder_pan_link.STL" />
      </geometry>
      <material
        name="">
        <color
          rgba="0.529411764705882 0.549019607843137 0.549019607843137 1" />
      </material>
    </visual>
    <collision>
      <origin
        xyz="0 0 0"
        rpy="0 0 0" />
      <geometry>
        <mesh
          filename="package://rbt_description/meshes/shoulder_pan_link.STL" />
      </geometry>
    </collision>
  </link>
  <joint
    name="shoulder_pan_joint"
    type="revolute">
    <origin
      xyz="0.16 0 0.545"
      rpy="-3.54831426125384E-43 -1.01364733915118E-30 0" />
    <parent
      link="torso_link" />
    <child
      link="shoulder_pan_link" />
    <axis
      xyz="0 0 1" />
      <dynamics damping="1.0" />
    <limit effort="33.82" lower="-1.6056" upper="1.6056" velocity="1.256" />
  </joint>
  <link
    name="shoulder_lift_link">
    <inertial>
      <origin
        xyz="0.051820706413111 0.00624292010541774 0.000567029072991554"
        rpy="0 0 0" />
       <mass value="2.6615" />
      <inertia ixx="0.0028" ixy="-0.0021" ixz="-0.0" iyy="0.0111" iyz="-0.0" izz="0.0112" />
    </inertial>
    <visual>
      <origin
        xyz="0 0 0"
        rpy="0 0 0" />
      <geometry>
        <mesh
          filename="package://rbt_description/meshes/shoulder_lift_link.STL" />
      </geometry>
      <material
        name="">
        <color
          rgba="0.529411764705882 0.549019607843137 0.549019607843137 1" />
      </material>
    </visual>
    <collision>
      <origin
        xyz="0 0 0"
        rpy="0 0 0" />
      <geometry>
        <mesh
          filename="package://rbt_description/meshes/shoulder_lift_link.STL" />
      </geometry>
    </collision>
  </link>
  <joint
    name="shoulder_lift_joint"
    type="revolute">
    <origin
      xyz="0.139999999999999 0.0275000000000008 0.0799999999999998"
      rpy="-3.47545734981105E-43 0 0" />
    <parent
      link="shoulder_pan_link" />
    <child
      link="shoulder_lift_link" />
    <axis
      xyz="0 1 0" />
       <dynamics damping="1.0" />
    <limit effort="131.76" lower="-1.221" upper="1.518" velocity="1.454" />
  </joint>

  <link
    name="upperarm_roll_link">
    <inertial>
      <origin
        xyz="0.0579889577743458 -0.00640364383298252 0.000719095115532253"
        rpy="0 0 0" />
      <mass value="2.3311" />
      <inertia ixx="0.0019" ixy="-0.0001" ixz="0.0" iyy="0.0045" iyz="0.0" izz="0.0047" />
    </inertial>
    <visual>
      <origin
        xyz="0 0 0"
        rpy="0 0 0" />
      <geometry>
        <mesh
          filename="package://rbt_description/meshes/upperarm_roll_link.STL" />
      </geometry>
      <material
        name="">
        <color
          rgba="0.529411764705882 0.549019607843137 0.549019607843137 1" />
      </material>
    </visual>
    <collision>
      <origin
        xyz="0 0 0"
        rpy="0 0 0" />
      <geometry>
        <mesh
          filename="package://rbt_description/meshes/upperarm_roll_link.STL" />
      </geometry>
    </collision>
  </link>
  <joint
    name="upperarm_roll_joint"
    type="continuous">
    <origin
      xyz="0.100000000000014 0 0"
      rpy="-3.47545734981105E-43 1.01364733915118E-30 0" />
    <parent
      link="shoulder_lift_link" />
    <child
      link="upperarm_roll_link" />
    <axis
      xyz="1 0 0" />
    <dynamics damping="5.0" />
    <limit effort="76.94" velocity="1.571" />
  </joint>
  <link
    name="elbow_flex_link">
    <inertial>
      <origin
        xyz="0.0518207064130914 0.00624292010542222 0.000567029072995107"
        rpy="0 0 0" />
      <mass value="2.1299" />
      <inertia ixx="0.0024" ixy="-0.0016" ixz="0.0" iyy="0.0082" iyz="-0.0" izz="0.0084" />
    </inertial>
    <visual>
      <origin
        xyz="0 0 0"
        rpy="0 0 0" />
      <geometry>
        <mesh
          filename="package://rbt_description/meshes/elbow_flex_link.STL" />
      </geometry>
      <material
        name="">
        <color
          rgba="0.529411764705882 0.549019607843137 0.549019607843137 1" />
      </material>
    </visual>
    <collision>
      <origin
        xyz="0 0 0"
        rpy="0 0 0" />
      <geometry>
        <mesh
          filename="package://rbt_description/meshes/elbow_flex_link.STL" />
      </geometry>
    </collision>
  </link>
  <joint
    name="elbow_flex_joint"
    type="revolute">
    <origin
      xyz="0.10000000000001 0.000172781781224759 0.0012087169179047"
      rpy="-3.54831426125384E-43 -1.01364733915118E-30 0" />
    <parent
      link="upperarm_roll_link" />
    <child
      link="elbow_flex_link" />
    <axis
      xyz="0 1 0" />
      <dynamics damping="1.0" />
    <limit effort="66.18" lower="-2.251" upper="2.251" velocity="1.521" />
  </joint>
  <link
    name="forearm_roll_link">
    <inertial>
      <origin
        xyz="0.0571818350174887 -0.0185958660157071 3.39530593640447E-08"
        rpy="0 0 0" />
       <mass value="1.6563" />
      <inertia ixx="0.0016" ixy="-0.0003" ixz="0.0" iyy="0.003" iyz="-0.0" izz="0.0035" />
    </inertial>
    <visual>
      <origin
        xyz="0 0 0"
        rpy="0 0 0" />
      <geometry>
        <mesh
          filename="package://rbt_description/meshes/forearm_roll_link.STL" />
      </geometry>
      <material
        name="">
        <color
          rgba="0.792156862745098 0.819607843137255 0.933333333333333 1" />
      </material>
    </visual>
    <collision>
      <origin
        xyz="0 0 0"
        rpy="0 0 0" />
      <geometry>
        <mesh
          filename="package://rbt_description/meshes/forearm_roll_link.STL" />
      </geometry>
    </collision>
  </link>
  <joint
    name="forearm_roll_joint"
    type="continuous">
    <origin
      xyz="0.1 0 0"
      rpy="-3.47545734981105E-43 0 0" />
    <parent
      link="elbow_flex_link" />
    <child
      link="forearm_roll_link" />
    <axis
      xyz="1 0 0" />
    <dynamics damping="5.0" />
    <limit effort="29.35" velocity="1.571" />
  </joint>
  <link
    name="wrist_flex_link">
    <inertial>
      <origin
        xyz="0.0419094188030202 0.000615572833431995 7.2819355656506E-08"
        rpy="0 0 0" />
     <mass value="1.725" />
      <inertia ixx="0.0018" ixy="-0.0001" ixz="-0.0" iyy="0.0042" iyz="0.0" izz="0.0042" />
    </inertial>
    <visual>
      <origin
        xyz="0 0 0"
        rpy="0 0 0" />
      <geometry>
        <mesh
          filename="package://rbt_description/meshes/wrist_flex_link.STL" />
      </geometry>
      <material
        name="">
        <color
          rgba="0.792156862745098 0.819607843137255 0.933333333333333 1" />
      </material>
    </visual>
    <collision>
      <origin
        xyz="0 0 0"
        rpy="0 0 0" />
      <geometry>
        <mesh
          filename="package://rbt_description/meshes/wrist_flex_link.STL" />
      </geometry>
    </collision>
  </link>
  <joint
    name="wrist_flex_joint"
    type="revolute">
    <origin
      xyz="0.126633249580691 -0.00252269168014944 0"
      rpy="-3.47545734981105E-43 0 0" />
    <parent
      link="forearm_roll_link" />
    <child
      link="wrist_flex_link" />
    <axis
      xyz="0 1 0" />
    <dynamics damping="1.0" />
    <limit effort="25.7" lower="-2.16" upper="2.16" velocity="2.268" />
  </joint>
  <link
    name="wrist_roll_link">
    <inertial>
      <origin
        xyz="0.0114601769911562 -4.58660887048268E-15 -3.44169137633799E-15"
        rpy="0 0 0" />
      <mass value="0.1354" />
      <inertia ixx="0.0001" ixy="0.0" ixz="0.0" iyy="0.0001" iyz="0.0" izz="0.0001" />
    </inertial>
    <visual>
      <origin
        xyz="0 0 0"
        rpy="0 0 0" />
      <geometry>
        <mesh
          filename="package://rbt_description/meshes/wrist_roll_link.STL" />
      </geometry>
      <material
        name="">
        <color
          rgba="0.792156862745098 0.819607843137255 0.933333333333333 1" />
      </material>
    </visual>
    <collision>
      <origin
        xyz="0 0 0"
        rpy="0 0 0" />
      <geometry>
        <mesh
          filename="package://rbt_description/meshes/wrist_roll_link.STL" />
      </geometry>
    </collision>
  </link>
  <joint
    name="wrist_roll_joint"
    type="continuous">
    <origin
      xyz="0.12 0 0"
      rpy="-3.47545734981105E-43 0 0" />
    <parent
      link="wrist_flex_link" />
    <child
      link="wrist_roll_link" />
    <axis
      xyz="1 0 0" />
    <limit effort="7.36" velocity="2.268" />
    <dynamics damping="5.0" />
  </joint>
  <link
    name="gripper_link">
    <inertial>
      <origin
        xyz="0.010424025963184 4.75661177112841E-15 5.44009282066327E-15"
        rpy="0 0 0" />
       <mass value="1.5175" />
      <inertia ixx="0.0013" ixy="-0.0" ixz="0.0" iyy="0.0019" iyz="-0.0" izz="0.0024" />
    </inertial>
    <visual>
      <origin
        xyz="0 0 0"
        rpy="0 0 0" />
      <geometry>
        <mesh
          filename="package://rbt_description/meshes/gripper_link.STL" />
      </geometry>
      <material
        name="">
        <color
          rgba="0.792156862745098 0.819607843137255 0.933333333333333 1" />
      </material>
    </visual>
    <collision>
      <origin
        xyz="0 0 0"
        rpy="0 0 0" />
      <geometry>
        <mesh
          filename="package://rbt_description/meshes/gripper_link.STL" />
      </geometry>
    </collision>
  </link>
  <joint
    name="gripper_joint"
    type="fixed">
    <origin
      xyz="0.02 0 0"
      rpy="-3.4755E-43 0 0" />
    <parent
      link="wrist_roll_link" />
    <child
      link="gripper_link" />
    <axis
      xyz="0 0 0" />
  </joint>
  <link
    name="l_gripper_link">
    <inertial>
      <origin
        xyz="0.00999999999999956 1.32185928869433E-14 -4.44089209850063E-16"
        rpy="0 0 0" />
        <mass value="0.0798" />
      <inertia ixx="0.002" ixy="0" ixz="0" iyy="0" iyz="0" izz="0" />
    </inertial>
    <visual>
      <origin
        xyz="0 0 0"
        rpy="0 0 0" />
      <geometry>
        <mesh
          filename="package://rbt_description/meshes/l_gripper_link.STL" />
      </geometry>
      <material
        name="">
        <color
          rgba="0.792156862745098 0.819607843137255 0.933333333333333 1" />
      </material>
    </visual>
    <collision>
      <origin
        xyz="0 0 0"
        rpy="0 0 0" />
      <geometry>
        <mesh
          filename="package://rbt_description/meshes/l_gripper_link.STL" />
      </geometry>
    </collision>
  </link>
  <joint
    name="l_gripper_joint"
    type="prismatic">
    <origin
      xyz="0.0199999999999914 0.0114999999999914 0"
      rpy="-3.47545734981105E-43 0 0" />
    <parent
      link="gripper_link" />
    <child
      link="l_gripper_link" />
    <axis
      xyz="0 -1 0" />
    <dynamics damping="100.0" />
    <limit effort="60" lower="-0.005" upper="0.01" velocity="0.05" />
  </joint>
  <link
    name="r_gripper_link">
    <inertial>
      <origin
        xyz="0.01 -1.33192068485499E-14 2.22044604925031E-16"
        rpy="0 0 0" />
      <mass value="0.0798" />
      <inertia ixx="0.002" ixy="0" ixz="0" iyy="0" iyz="0" izz="0" />
    </inertial>
    <visual>
      <origin
        xyz="0 0 0"
        rpy="0 0 0" />
      <geometry>
        <mesh
          filename="package://rbt_description/meshes/r_gripper_link.STL" />
      </geometry>
      <material
        name="">
        <color
          rgba="0.792156862745098 0.819607843137255 0.933333333333333 1" />
      </material>
    </visual>
    <collision>
      <origin
        xyz="0 0 0"
        rpy="0 0 0" />
      <geometry>
        <mesh
          filename="package://rbt_description/meshes/r_gripper_link.STL" />
      </geometry>
    </collision>
  </link>
  <joint
    name="r_gripper_joint"
    type="prismatic">
    <origin
      xyz="0.0199999999999908 -0.0114999999999821 0"
      rpy="-3.47545734981105E-43 0 0" />
    <parent
      link="gripper_link" />
    <child
      link="r_gripper_link" />
    <axis
      xyz="0 1 0" />
    <dynamics damping="100.0" />
    <limit effort="60" lower="-0.005" upper="0.01" velocity="0.05" />
  </joint>
</robot>