<?xml version="1.0"?>
<robot name="rbt" xmlns:xacro="http://www.ros.org/wiki/xacro">
 <xacro:include filename="$(find rbt_gazebo)/robots/rbt.gazebo.xacro" />
  <link
    name="base_link">
    <inertial>
      <origin
        xyz="1.61180778117708E-17 0.105338647334788 -3.58247598962808E-05"
        rpy="0 0 0" />
      <mass
        value="70.1294" />
      <inertia
        ixx="1.225" ixy="0.0099" ixz="0.0062" iyy="1.2853" iyz="-0.0034" izz="0.987" />
    </inertial>
    <visual>
      <origin
        xyz="0 0 0"
        rpy="0 0 0" />
      <geometry>
        <mesh
          filename="package://rbt_description/meshes/base_link.STL" />
      </geometry>
      <material
        name="Black">
        <color
          rgba="0.3 0.3 0.3 1.0" />
      </material>
    </visual>
    <collision>
      <origin
        xyz="0 0 0"
        rpy="0 0 0" />
      <geometry>
        <mesh
          filename="package://rbt_description/meshes/base_link.STL" />
      </geometry>
    </collision>
  </link>
  <link
    name="l_wheel_link">
    <inertial>
      <origin
        xyz="3.5354E-16 6.9389E-18 0.015"
        rpy="0 0 0" />
      <mass
        value="4.3542" />
      <inertia
       ixx="0.0045" ixy="0" ixz="0" iyy="0.005" iyz="0" izz="0.0045"  />
    </inertial>
    <visual>
      <origin
        xyz="0 0 0"
        rpy="0 0 0" />
      <geometry>
        <mesh
          filename="package://rbt_description/meshes/l_wheel_link.STL" />
      </geometry>
      <material
        name="">
        <color
          rgba="0 0.17255 1 1" />
      </material>
    </visual>
    <collision>
      <origin
        xyz="0 0 0"
        rpy="0 0 0" />
      <geometry>
        <mesh
          filename="package://rbt_description/meshes/l_wheel_link.STL" />
      </geometry>
    </collision>
  </link>
  <joint
    name="l_wheel_joint"
    type="continuous">
    <origin
      xyz="0.165 0 0.05"
      rpy="1.5708 6.123E-17 1.5708" />
    <parent
      link="base_link" />
    <child
      link="l_wheel_link" />
    <axis
      xyz="0 0 1" />
  </joint>
  <link
    name="r_wheel_link">
    <inertial>
      <origin
        xyz="-9.0369E-16 6.9389E-18 -0.015"
        rpy="0 0 0" />
      <mass
        value="4.3542" />
      <inertia
        ixx="0.0045" ixy="0" ixz="0" iyy="0.005" iyz="0" izz="0.0045" />
    </inertial>
    <visual>
      <origin
        xyz="0 0 0"
        rpy="0 0 0" />
      <geometry>
        <mesh
          filename="package://rbt_description/meshes/r_wheel_link.STL" />
      </geometry>
      <material
        name="">
        <color
          rgba="0 0.17255 1 1" />
      </material>
    </visual>
    <collision>
      <origin
        xyz="0 0 0"
        rpy="0 0 0" />
      <geometry>
        <mesh
          filename="package://rbt_description/meshes/r_wheel_link.STL" />
      </geometry>
    </collision>
  </link>
  <joint
    name="r_wheel_joint"
    type="continuous">
    <origin
      xyz="-0.165 0 0.05"
      rpy="1.5708 6.123E-17 1.5708" />
    <parent
      link="base_link" />
    <child
      link="r_wheel_link" />
    <axis
      xyz="0 0 1" />
  </joint>
  <link
    name="laser_link">
    <inertial>
      <origin
        xyz="3.2198E-17 -0.0042085 0"
        rpy="0 0 0" />
      <mass
        value="4.3542" />
      <inertia
        ixx="0"
        ixy="0"
        ixz="0"
        iyy="0"
        iyz="0"
        izz="0" />
    </inertial>
    <visual>
      <origin
        xyz="0 0 0"
        rpy="0 0 0" />
      <geometry>
        <mesh
          filename="package://rbt_description/meshes/laser_link.STL" />
      </geometry>
      <material
        name="">
        <color
          rgba="0.79216 0.81961 0.93333 1" />
      </material>
    </visual>
    <collision>
      <origin
        xyz="0 0 0"
        rpy="0 0 0" />
      <geometry>
        <mesh
          filename="package://rbt_description/meshes/laser_link.STL" />
      </geometry>
    </collision>
  </link>
  <joint
    name="laser_joint"
    type="fixed">
    <origin
      xyz="0 -0.21 0.212"
      rpy="1.5708 0 0" />
    <parent
      link="base_link" />
    <child
      link="laser_link" />
    <axis
      xyz="0 0 0" />
  </joint>
</robot>