<?xml version="1.0"?>
<robot name="rbt" xmlns:xacro="http://www.ros.org/wiki/xacro">
 <xacro:include filename="$(find rbt_gazebo)/robots/rbt.gazebo.xacro" />
  <link
    name="base_link">
    <inertial>
      <origin
        xyz="1.5170507548791E-17 -0.000197277236774495 0.0803276867224908"
        rpy="0 0 0" />
      <mass
        value="190.047063870531" />
      <inertia
        ixx="0.00513222256327552"
        ixy="1.43114686768087E-17"
        ixz="3.46944695195361E-18"
        iyy="0.0118016516978085"
        iyz="-0.00113704440589145"
        izz="0.0164025460146906" />
    </inertial>
    <visual>
      <origin
        xyz="0 0 0"
        rpy="0 0 0" />
      <geometry>
        <mesh
          filename="package://rbt_description/meshes/base_link.STL" />
      </geometry>
      <material
        name="">
        <color
          rgba="0.752941176470588 0.752941176470588 0.752941176470588 1" />
      </material>
    </visual>
    <collision>
      <origin
        xyz="0 0 0"
        rpy="0 0 0" />
      <geometry>
        <mesh
          filename="package://rbt_description/meshes/base_link.STL" />
      </geometry>
    </collision>
  </link>
  <link
    name="l_wheel_link">
    <inertial>
      <origin
        xyz="0 0 0.015"
        rpy="0 0 0" />
      <mass
        value="0.144199844682647" />
      <inertia
        ixx="0"
        ixy="0"
        ixz="0"
        iyy="0"
        iyz="0"
        izz="0" />
    </inertial>
    <visual>
      <origin
        xyz="0 0 0"
        rpy="0 0 0" />
      <geometry>
        <mesh
          filename="package://rbt_description/meshes/l_wheel_link.STL" />
      </geometry>
      <material
        name="">
        <color
          rgba="1 1 1 1" />
      </material>
    </visual>
    <collision>
      <origin
        xyz="0 0 0"
        rpy="0 0 0" />
      <geometry>
        <mesh
          filename="package://rbt_description/meshes/l_wheel_link.STL" />
      </geometry>
    </collision>
  </link>
  <joint
    name="l_wheel_joint"
    type="continuous">
    <origin
      xyz="0.185 0.13 0.05"
      rpy="1.5707963267949 6.12303176911189E-17 1.5707963267949" />
    <parent
      link="base_link" />
    <child
      link="l_wheel_link" />
    <axis
      xyz="0 0 1" />
  </joint>
  <link
    name="r_wheel_link">
    <inertial>
      <origin
        xyz="-5.55111512312578E-17 6.93889390390723E-18 -0.015"
        rpy="0 0 0" />
      <mass
        value="0.144199844682647" />
      <inertia
        ixx="0"
        ixy="0"
        ixz="0"
        iyy="0"
        iyz="0"
        izz="0" />
    </inertial>
    <visual>
      <origin
        xyz="0 0 0"
        rpy="0 0 0" />
      <geometry>
        <mesh
          filename="package://rbt_description/meshes/r_wheel_link.STL" />
      </geometry>
      <material
        name="">
        <color
          rgba="1 1 1 1" />
      </material>
    </visual>
    <collision>
      <origin
        xyz="0 0 0"
        rpy="0 0 0" />
      <geometry>
        <mesh
          filename="package://rbt_description/meshes/r_wheel_link.STL" />
      </geometry>
    </collision>
  </link>
  <joint
    name="r_wheel_joint"
    type="continuous">
    <origin
      xyz="-0.185 0.129999999999999 0.0500000000000007"
      rpy="1.5707963267949 6.12303176911189E-17 1.5707963267949" />
    <parent
      link="base_link" />
    <child
      link="r_wheel_link" />
    <axis
      xyz="0 0 1" />
  </joint>
</robot>